<?xml version="1.0" encoding="UTF-8"?>
<!-- Generated by org.testng.reporters.JUnitReportReporter -->
<testsuite hostname="QT-INBG-LT0912" failures="5" tests="5" name="com.qualitestgroup.qualidexexcelutility.Unit_Test" time="0.974" errors="0" timestamp="22 Jul 2022 08:03:22 GMT" skipped="0">
  <testcase classname="com.qualitestgroup.qualidexexcelutility.Unit_Test" name="qualidexImageTest" time="0.027">
    <failure message="Test case failed due to  
	expected [true] but found [false]" type="java.lang.AssertionError">
      <![CDATA[java.lang.AssertionError: Test case failed due to  
expected [true] but found [false]
at com.qualitestgroup.data_extract_demo.damoregroup.Softassert.assertAll(Softassert.java:55)
at com.qualitestgroup.qualidexexcelutility.Unit_Test.qualidexImageTest(Unit_Test.java:150)
at java.base/jdk.internal.reflect.NativeMethodAccessorImpl.invoke0(Native Method)
at java.base/jdk.internal.reflect.NativeMethodAccessorImpl.invoke(NativeMethodAccessorImpl.java:62)
at java.base/jdk.internal.reflect.DelegatingMethodAccessorImpl.invoke(DelegatingMethodAccessorImpl.java:43)
at java.base/java.lang.reflect.Method.invoke(Method.java:566)
at org.testng.internal.MethodInvocationHelper.invokeMethod(MethodInvocationHelper.java:124)
at org.testng.internal.Invoker.invokeMethod(Invoker.java:583)
at org.testng.internal.Invoker.invokeTestMethod(Invoker.java:719)
at org.testng.internal.Invoker.invokeTestMethods(Invoker.java:989)
at org.testng.internal.TestMethodWorker.invokeTestMethods(TestMethodWorker.java:125)
at org.testng.internal.TestMethodWorker.run(TestMethodWorker.java:109)
at org.testng.TestRunner.privateRun(TestRunner.java:648)
at org.testng.TestRunner.run(TestRunner.java:505)
at org.testng.SuiteRunner.runTest(SuiteRunner.java:455)
at org.testng.SuiteRunner.runSequentially(SuiteRunner.java:450)
at org.testng.SuiteRunner.privateRun(SuiteRunner.java:415)
at org.testng.SuiteRunner.run(SuiteRunner.java:364)
at org.testng.SuiteRunnerWorker.runSuite(SuiteRunnerWorker.java:52)
at org.testng.SuiteRunnerWorker.run(SuiteRunnerWorker.java:84)
at org.testng.TestNG.runSuitesSequentially(TestNG.java:1208)
at org.testng.TestNG.runSuitesLocally(TestNG.java:1137)
at org.testng.TestNG.runSuites(TestNG.java:1049)
at org.testng.TestNG.run(TestNG.java:1017)
at org.testng.remote.AbstractRemoteTestNG.run(AbstractRemoteTestNG.java:115)
at org.testng.remote.RemoteTestNG.initAndRun(RemoteTestNG.java:251)
at org.testng.remote.RemoteTestNG.main(RemoteTestNG.java:77)
]]>
    </failure>
  </testcase> <!-- qualidexImageTest -->
  <testcase classname="com.qualitestgroup.qualidexexcelutility.Unit_Test" name="qualidexLibraryTest3" time="0.813">
    <failure message="Test case failed due to Multiple Assertion failures
	expected [true] but found [false],
	Header appears 0 times and is not found in PDF expected [true] but found [false],
	Head is not found in the PDF expected [true] but found [false]" type="java.lang.AssertionError">
      <![CDATA[java.lang.AssertionError: Test case failed due to Multiple Assertion failures
expected [true] but found [false],
Header appears 0 times and is not found in PDF expected [true] but found [false],
Head is not found in the PDF expected [true] but found [false]
at com.qualitestgroup.data_extract_demo.damoregroup.Softassert.assertAll(Softassert.java:55)
at com.qualitestgroup.qualidexexcelutility.Unit_Test.qualidexLibraryTest3(Unit_Test.java:130)
at java.base/jdk.internal.reflect.NativeMethodAccessorImpl.invoke0(Native Method)
at java.base/jdk.internal.reflect.NativeMethodAccessorImpl.invoke(NativeMethodAccessorImpl.java:62)
at java.base/jdk.internal.reflect.DelegatingMethodAccessorImpl.invoke(DelegatingMethodAccessorImpl.java:43)
at java.base/java.lang.reflect.Method.invoke(Method.java:566)
at org.testng.internal.MethodInvocationHelper.invokeMethod(MethodInvocationHelper.java:124)
at org.testng.internal.Invoker.invokeMethod(Invoker.java:583)
at org.testng.internal.Invoker.invokeTestMethod(Invoker.java:719)
at org.testng.internal.Invoker.invokeTestMethods(Invoker.java:989)
at org.testng.internal.TestMethodWorker.invokeTestMethods(TestMethodWorker.java:125)
at org.testng.internal.TestMethodWorker.run(TestMethodWorker.java:109)
at org.testng.TestRunner.privateRun(TestRunner.java:648)
at org.testng.TestRunner.run(TestRunner.java:505)
at org.testng.SuiteRunner.runTest(SuiteRunner.java:455)
at org.testng.SuiteRunner.runSequentially(SuiteRunner.java:450)
at org.testng.SuiteRunner.privateRun(SuiteRunner.java:415)
at org.testng.SuiteRunner.run(SuiteRunner.java:364)
at org.testng.SuiteRunnerWorker.runSuite(SuiteRunnerWorker.java:52)
at org.testng.SuiteRunnerWorker.run(SuiteRunnerWorker.java:84)
at org.testng.TestNG.runSuitesSequentially(TestNG.java:1208)
at org.testng.TestNG.runSuitesLocally(TestNG.java:1137)
at org.testng.TestNG.runSuites(TestNG.java:1049)
at org.testng.TestNG.run(TestNG.java:1017)
at org.testng.remote.AbstractRemoteTestNG.run(AbstractRemoteTestNG.java:115)
at org.testng.remote.RemoteTestNG.initAndRun(RemoteTestNG.java:251)
at org.testng.remote.RemoteTestNG.main(RemoteTestNG.java:77)
]]>
    </failure>
  </testcase> <!-- qualidexLibraryTest3 -->
  <testcase classname="com.qualitestgroup.qualidexexcelutility.Unit_Test" name="qualidexLibraryTest4" time="0.011">
    <failure message="Test case failed due to Multiple Assertion failures
	expected [true] but found [false],
	Header appears 0 times and is not found in PDF expected [true] but found [false],
	Head is not found in the PDF expected [true] but found [false]" type="java.lang.AssertionError">
      <![CDATA[java.lang.AssertionError: Test case failed due to Multiple Assertion failures
expected [true] but found [false],
Header appears 0 times and is not found in PDF expected [true] but found [false],
Head is not found in the PDF expected [true] but found [false]
at com.qualitestgroup.data_extract_demo.damoregroup.Softassert.assertAll(Softassert.java:55)
at com.qualitestgroup.qualidexexcelutility.Unit_Test.qualidexLibraryTest4(Unit_Test.java:143)
at java.base/jdk.internal.reflect.NativeMethodAccessorImpl.invoke0(Native Method)
at java.base/jdk.internal.reflect.NativeMethodAccessorImpl.invoke(NativeMethodAccessorImpl.java:62)
at java.base/jdk.internal.reflect.DelegatingMethodAccessorImpl.invoke(DelegatingMethodAccessorImpl.java:43)
at java.base/java.lang.reflect.Method.invoke(Method.java:566)
at org.testng.internal.MethodInvocationHelper.invokeMethod(MethodInvocationHelper.java:124)
at org.testng.internal.Invoker.invokeMethod(Invoker.java:583)
at org.testng.internal.Invoker.invokeTestMethod(Invoker.java:719)
at org.testng.internal.Invoker.invokeTestMethods(Invoker.java:989)
at org.testng.internal.TestMethodWorker.invokeTestMethods(TestMethodWorker.java:125)
at org.testng.internal.TestMethodWorker.run(TestMethodWorker.java:109)
at org.testng.TestRunner.privateRun(TestRunner.java:648)
at org.testng.TestRunner.run(TestRunner.java:505)
at org.testng.SuiteRunner.runTest(SuiteRunner.java:455)
at org.testng.SuiteRunner.runSequentially(SuiteRunner.java:450)
at org.testng.SuiteRunner.privateRun(SuiteRunner.java:415)
at org.testng.SuiteRunner.run(SuiteRunner.java:364)
at org.testng.SuiteRunnerWorker.runSuite(SuiteRunnerWorker.java:52)
at org.testng.SuiteRunnerWorker.run(SuiteRunnerWorker.java:84)
at org.testng.TestNG.runSuitesSequentially(TestNG.java:1208)
at org.testng.TestNG.runSuitesLocally(TestNG.java:1137)
at org.testng.TestNG.runSuites(TestNG.java:1049)
at org.testng.TestNG.run(TestNG.java:1017)
at org.testng.remote.AbstractRemoteTestNG.run(AbstractRemoteTestNG.java:115)
at org.testng.remote.RemoteTestNG.initAndRun(RemoteTestNG.java:251)
at org.testng.remote.RemoteTestNG.main(RemoteTestNG.java:77)
]]>
    </failure>
  </testcase> <!-- qualidexLibraryTest4 -->
  <testcase classname="com.qualitestgroup.qualidexexcelutility.Unit_Test" name="qualidexLibraryTest1" time="0.105">
    <failure message="Test case failed due to Multiple Assertion failures
	expected [true] but found [false],
	Header appears 0 times and is not found in PDF expected [true] but found [false],
	Head is not found in the PDF expected [true] but found [false],
	Test Invalid content is not found in the PDF expected [true] but found [false],
	Test invalid content2 is not found in the PDF expected [true] but found [false],
	Here the Messages is received by Subscribers. The message is processed 
and marked valid or invalid is not found in the PDF expected [true] but found [false],
	Test Invalid content 3 is not found in the PDF expected [true] but found [false]" type="java.lang.AssertionError">
      <![CDATA[java.lang.AssertionError: Test case failed due to Multiple Assertion failures
expected [true] but found [false],
Header appears 0 times and is not found in PDF expected [true] but found [false],
Head is not found in the PDF expected [true] but found [false],
Test Invalid content is not found in the PDF expected [true] but found [false],
Test invalid content2 is not found in the PDF expected [true] but found [false],
Here the Messages is received by Subscribers. The message is processed 
and marked valid or invalid is not found in the PDF expected [true] but found [false],
Test Invalid content 3 is not found in the PDF expected [true] but found [false]
at com.qualitestgroup.data_extract_demo.damoregroup.Softassert.assertAll(Softassert.java:55)
at com.qualitestgroup.qualidexexcelutility.Unit_Test.qualidexLibraryTest1(Unit_Test.java:66)
at java.base/jdk.internal.reflect.NativeMethodAccessorImpl.invoke0(Native Method)
at java.base/jdk.internal.reflect.NativeMethodAccessorImpl.invoke(NativeMethodAccessorImpl.java:62)
at java.base/jdk.internal.reflect.DelegatingMethodAccessorImpl.invoke(DelegatingMethodAccessorImpl.java:43)
at java.base/java.lang.reflect.Method.invoke(Method.java:566)
at org.testng.internal.MethodInvocationHelper.invokeMethod(MethodInvocationHelper.java:124)
at org.testng.internal.Invoker.invokeMethod(Invoker.java:583)
at org.testng.internal.Invoker.invokeTestMethod(Invoker.java:719)
at org.testng.internal.Invoker.invokeTestMethods(Invoker.java:989)
at org.testng.internal.TestMethodWorker.invokeTestMethods(TestMethodWorker.java:125)
at org.testng.internal.TestMethodWorker.run(TestMethodWorker.java:109)
at org.testng.TestRunner.privateRun(TestRunner.java:648)
at org.testng.TestRunner.run(TestRunner.java:505)
at org.testng.SuiteRunner.runTest(SuiteRunner.java:455)
at org.testng.SuiteRunner.runSequentially(SuiteRunner.java:450)
at org.testng.SuiteRunner.privateRun(SuiteRunner.java:415)
at org.testng.SuiteRunner.run(SuiteRunner.java:364)
at org.testng.SuiteRunnerWorker.runSuite(SuiteRunnerWorker.java:52)
at org.testng.SuiteRunnerWorker.run(SuiteRunnerWorker.java:84)
at org.testng.TestNG.runSuitesSequentially(TestNG.java:1208)
at org.testng.TestNG.runSuitesLocally(TestNG.java:1137)
at org.testng.TestNG.runSuites(TestNG.java:1049)
at org.testng.TestNG.run(TestNG.java:1017)
at org.testng.remote.AbstractRemoteTestNG.run(AbstractRemoteTestNG.java:115)
at org.testng.remote.RemoteTestNG.initAndRun(RemoteTestNG.java:251)
at org.testng.remote.RemoteTestNG.main(RemoteTestNG.java:77)
]]>
    </failure>
  </testcase> <!-- qualidexLibraryTest1 -->
  <testcase classname="com.qualitestgroup.qualidexexcelutility.Unit_Test" name="qualidexLibraryTest2" time="0.018">
    <failure message="Test case failed due to Multiple Assertion failures
	expected [true] but found [false],
	Header appears 0 times and is not found in PDF expected [true] but found [false],
	Head is not found in the PDF expected [true] but found [false],
	Test Invalid content is not found in the PDF expected [true] but found [false],
	Test invalid content2 is not found in the PDF expected [true] but found [false],
	Here the Messages is received by Subscribers. The message is processed 
and marked valid or invalid is not found in the PDF expected [true] but found [false],
	Test Invalid content 3 is not found in the PDF expected [true] but found [false],
	Header not found expected [true] but found [false],
	Header not found expected [true] but found [false],
	Footer not found expected [true] but found [false],
	Footer not found expected [true] but found [false]" type="java.lang.AssertionError">
      <![CDATA[java.lang.AssertionError: Test case failed due to Multiple Assertion failures
expected [true] but found [false],
Header appears 0 times and is not found in PDF expected [true] but found [false],
Head is not found in the PDF expected [true] but found [false],
Test Invalid content is not found in the PDF expected [true] but found [false],
Test invalid content2 is not found in the PDF expected [true] but found [false],
Here the Messages is received by Subscribers. The message is processed 
and marked valid or invalid is not found in the PDF expected [true] but found [false],
Test Invalid content 3 is not found in the PDF expected [true] but found [false],
Header not found expected [true] but found [false],
Header not found expected [true] but found [false],
Footer not found expected [true] but found [false],
Footer not found expected [true] but found [false]
at com.qualitestgroup.data_extract_demo.damoregroup.Softassert.assertAll(Softassert.java:55)
at com.qualitestgroup.qualidexexcelutility.Unit_Test.qualidexLibraryTest2(Unit_Test.java:113)
at java.base/jdk.internal.reflect.NativeMethodAccessorImpl.invoke0(Native Method)
at java.base/jdk.internal.reflect.NativeMethodAccessorImpl.invoke(NativeMethodAccessorImpl.java:62)
at java.base/jdk.internal.reflect.DelegatingMethodAccessorImpl.invoke(DelegatingMethodAccessorImpl.java:43)
at java.base/java.lang.reflect.Method.invoke(Method.java:566)
at org.testng.internal.MethodInvocationHelper.invokeMethod(MethodInvocationHelper.java:124)
at org.testng.internal.Invoker.invokeMethod(Invoker.java:583)
at org.testng.internal.Invoker.invokeTestMethod(Invoker.java:719)
at org.testng.internal.Invoker.invokeTestMethods(Invoker.java:989)
at org.testng.internal.TestMethodWorker.invokeTestMethods(TestMethodWorker.java:125)
at org.testng.internal.TestMethodWorker.run(TestMethodWorker.java:109)
at org.testng.TestRunner.privateRun(TestRunner.java:648)
at org.testng.TestRunner.run(TestRunner.java:505)
at org.testng.SuiteRunner.runTest(SuiteRunner.java:455)
at org.testng.SuiteRunner.runSequentially(SuiteRunner.java:450)
at org.testng.SuiteRunner.privateRun(SuiteRunner.java:415)
at org.testng.SuiteRunner.run(SuiteRunner.java:364)
at org.testng.SuiteRunnerWorker.runSuite(SuiteRunnerWorker.java:52)
at org.testng.SuiteRunnerWorker.run(SuiteRunnerWorker.java:84)
at org.testng.TestNG.runSuitesSequentially(TestNG.java:1208)
at org.testng.TestNG.runSuitesLocally(TestNG.java:1137)
at org.testng.TestNG.runSuites(TestNG.java:1049)
at org.testng.TestNG.run(TestNG.java:1017)
at org.testng.remote.AbstractRemoteTestNG.run(AbstractRemoteTestNG.java:115)
at org.testng.remote.RemoteTestNG.initAndRun(RemoteTestNG.java:251)
at org.testng.remote.RemoteTestNG.main(RemoteTestNG.java:77)
]]>
    </failure>
  </testcase> <!-- qualidexLibraryTest2 -->
</testsuite> <!-- com.qualitestgroup.qualidexexcelutility.Unit_Test -->
